Workbook

Sheet Baca Dulu
B2: Analisis Tipologi Klassen — Kabupaten/Kota Provinsi Kepulauan Riau
B4: Isi Workbook
B6: 1. Data PDRB ADHK
B7: Data mentah PDRB Atas Dasar Harga Konstan 2010 per 17 lapangan usaha, per kabupaten/kota, 2020-2025 (input asli dari file CSV kamu).
B9: 2. Data Penduduk
B10: Jumlah penduduk pertengahan tahun per kabupaten/kota, 2020-2025 (sumber: BPS Kepri, Proyeksi Penduduk Kab/Kota Kepri 2020-2035 Hasil SP2020).
B12: 3. Total PDRB & Per Kapita
B13: Total PDRB tiap kab/kota (jumlah 17 sektor) dan PDRB per kapita, dihitung otomatis pakai rumus dari sheet 1 & 2.
B15: 4. Laju Pertumbuhan
B16: Laju pertumbuhan ekonomi tahunan tiap kab/kota (2021-2025), dihitung dari sheet 3.
B18: 5. Tipologi Klassen
B19: Klasifikasi 4 kuadran tiap kab/kota per tahun, dibandingkan dengan rata-rata Provinsi Kepri. Ini hasil akhirnya.
... B28: Kuadran IV - Berkembang Cepat : PDRB per kapita < provinsi, TAPI pertumbuhan > provinsi

Sheet 1. Data PDRB ADHK
A1: Kabupaten_Kota | B1: No | C1: Kode | D1: Lapangan_Usaha | E1: 2020 | F1: 2021 | G1: 2022 | H1: 2023 | I1: 2024 | J1: 2025
A2: Kabupaten Karimun | B2: 1 | C2: A | D2: Pertanian, Kehutanan, dan Perikanan | E2: 1532.48 | F2: 1473.45 | G2: 1503.41 | H2: 1552.78 | I2: 1586.94 | J2: 1640.89
A3: Kabupaten Karimun | B3: 2 | C3: B | D3: Pertambangan dan Penggalian | E3: 877.74 | F3: 1010.73 | G3: 975.93 | H3: 955.9 | I3: 936.78 | J3: 974.25
A4: Kabupaten Karimun | B4: 3 | C4: C | D4: Industri Pengolahan | E4: 1213.98 | F4: 1235.09 | G4: 1269.55 | H4: 1366.48 | I4: 1724.91 | J4: 1931.9
A5: Kabupaten Karimun | B5: 4 | C5: D | D5: Pengadaan Listrik dan Gas | E5: 28.48 | F5: 28.53 | G5: 31.52 | H5: 35 | I5: 38.37 | J5: 42.2
A6: Kabupaten Karimun | B6: 5 | C6: E | D6: Pengadaan Air, Pengelolaan Sampah, Limbah dan Daur Ulang | E6: 4.15 | F6: 4.15 | G6: 4.37 | H6: 4.4 | I6: 4.53 | J6: 4.8
A7: Kabupaten Karimun | B7: 6 | C7: F | D7: Konstruksi | E7: 1742.8 | F7: 1852.57 | G7: 1923.17 | H7: 1958.48 | I7: 2062.28 | J7: 2175.7
A8: Kabupaten Karimun | B8: 7 | C8: G | D8: Perdagangan Besar dan Eceran dan Reparasi Mobil dan Sepeda Motor | E8: 1521.72 | F8: 1542.52 | G8: 1676.09 | H8: 1800.8 | I8: 1919.65 | J8: 2063.62
A9: Kabupaten Karimun | B9: 8 | C9: H | D9: Transportasi dan Pergudangan | E9: 243.77 | F9: 232.22 | G9: 283.17 | H9: 341 | I9: 361.46 | J9: 388.57
A10: Kabupaten Karimun | B10: 9 | C10: I | D10: Penyediaan Akomodasi dan Makan Minum | E10: 167.62 | F10: 171.54 | G10: 219.8 | H10: 258.85 | I10: 284.14 | J10: 301.19
A11: Kabupaten Karimun | B11: 10 | C11: J | D11: Informasi dan Komunikasi | E11: 357.3 | F11: 371.11 | G11: 390.39 | H11: 486.26 | I11: 508.14 | J11: 520.84
A12: Kabupaten Karimun | B12: 11 | C12: K | D12: Jasa Keuangan dan Asuransi | E12: 160.7 | F12: 161.22 | G12: 165.06 | H12: 177.49 | I12: 187.61 | J12: 195.3
A13: Kabupaten Karimun | B13: 12 | C13: L | D13: Real Estat | E13: 288.87 | F13: 296.37 | G13: 306.63 | H13: 318.8 | I13: 332.51 | J13: 349.14
... A120: Kota Tanjungpinang | B120: 17 | C120: R,S,T,U | D120: Jasa Lainnya | E120: 142.01 | F120: 138.06 | G120: 157.57 | H120: 172.72 | I120: 191.77 | J120: 195.53
A122: Satuan: Miliar Rupiah. Sumber: PDRB Kabupaten/Kota Provinsi Kepulauan Riau Menurut Lapangan Usaha 2020-2025 (BPS).

Sheet 2. Data Penduduk
A1: Kabupaten_Kota | B1: 2020 | C1: 2021 | D1: 2022 | E1: 2023 | F1: 2024 | G1: 2025
A2: Kabupaten Karimun | B2: 252.09 | C2: 254.96 | D2: 257.8 | E2: 260.6 | F2: 263.34 | G2: 266.01
A3: Kabupaten Bintan | B3: 158.77 | C3: 161.18 | D3: 163.56 | E3: 165.89 | F3: 168.19 | G3: 170.46
A4: Kabupaten Natuna | B4: 81.13 | C4: 82.28 | D4: 83.43 | E4: 84.56 | F4: 85.66 | G4: 86.76
A5: Kabupaten Lingga | B5: 97.99 | C5: 99.02 | D5: 100.03 | E5: 101.03 | F5: 102.01 | G5: 102.95
A6: Kabupaten Kepulauan Anambas | B6: 47.11 | C6: 47.78 | D6: 48.44 | E6: 49.09 | F6: 49.73 | G6: 50.36
A7: Kota Batam | B7: 1193.96 | C7: 1215.14 | D7: 1236.01 | E7: 1256.61 | F7: 1276.93 | G7: 1296.96
A8: Kota Tanjungpinang | B8: 226.81 | C8: 229.54 | D8: 232.2 | E8: 234.84 | F8: 237.43 | G8: 239.96
A9: Provinsi Kepulauan Riau | B9: 2057.86 | C9: 2089.89 | D9: 2121.48 | E9: 2152.63 | F9: 2183.29 | G9: 2213.46
A11: Satuan: Ribu jiwa (proyeksi pertengahan tahun/Juni). Sumber: BPS Kepri - Proyeksi Penduduk Kab/Kota Kepri 2020-2035 Hasil Sensus Penduduk 2020.

Sheet 3. Total PDRB & Per Kapita
A1: Kabupaten/Kota | B1: Komponen | C1: 2020 | D1: 2021 | E1: 2022 | F1: 2023 | G1: 2024 | H1: 2025
A2: Kabupaten Karimun | B2: Total PDRB (Miliar Rp) | C2: =SUMIF('1. Data PDRB ADHK'!$A$2:$A$120,$A2,'1. Data PDRB ADHK'!$E$2:$E$120) -> 9117.11 | D2: =SUMIF('1. Data PDRB ADHK'!$A$2:$A$120,$A2,'1. Data PDRB ADHK'!$F$2:$F$120) -> 9332.77 | E2: =SUMIF('1. Data PDRB ADHK'!$A$2:$A$120,$A2,'1. Data PDRB ADHK'!$G$2:$G$120) -> 9741.86 | F2: =SUMIF('1. Data PDRB ADHK'!$A$2:$A$120,$A2,'1. Data PDRB ADHK'!$H$2:$H$120) -> 10277.6 | G2: =SUMIF('1. Data PDRB ADHK'!$A$2:$A$120,$A2,'1. Data PDRB ADHK'!$I$2:$I$120) -> 11073.58 | H2: =SUMIF('1. Data PDRB ADHK'!$A$2:$A$120,$A2,'1. Data PDRB ADHK'!$J$2:$J$120) -> 11738.98
A3: Kabupaten Karimun | B3: Penduduk (Ribu Jiwa) | C3: ='2. Data Penduduk'!B2 -> 252.09 | D3: ='2. Data Penduduk'!C2 -> 254.96 | E3: ='2. Data Penduduk'!D2 -> 257.8 | F3: ='2. Data Penduduk'!E2 -> 260.6 | G3: ='2. Data Penduduk'!F2 -> 263.34 | H3: ='2. Data Penduduk'!G2 -> 266.01
A4: Kabupaten Karimun | B4: PDRB per Kapita (Juta Rp) | C4: =C2/C3 -> 36.166091 | D4: =D2/D3 -> 36.60484 | E4: =E2/E3 -> 37.788441 | F4: =F2/F3 -> 39.438219 | G4: =G2/G3 -> 42.050505 | H4: =H2/H3 -> 44.129845
A6: Kabupaten Bintan | B6: Total PDRB (Miliar Rp) | C6: =SUMIF('1. Data PDRB ADHK'!$A$2:$A$120,$A6,'1. Data PDRB ADHK'!$E$2:$E$120) -> 13902.16 | D6: =SUMIF('1. Data PDRB ADHK'!$A$2:$A$120,$A6,'1. Data PDRB ADHK'!$F$2:$F$120) -> 13933.47 | E6: =SUMIF('1. Data PDRB ADHK'!$A$2:$A$120,$A6,'1. Data PDRB ADHK'!$G$2:$G$120) -> 14551.77 | F6: =SUMIF('1. Data PDRB ADHK'!$A$2:$A$120,$A6,'1. Data PDRB ADHK'!$H$2:$H$120) -> 15445.29 | G6: =SUMIF('1. Data PDRB ADHK'!$A$2:$A$120,$A6,'1. Data PDRB ADHK'!$I$2:$I$120) -> 16967.59 | H6: =SUMIF('1. Data PDRB ADHK'!$A$2:$A$120,$A6,'1. Data PDRB ADHK'!$J$2:$J$120) -> 18287.81
A7: Kabupaten Bintan | B7: Penduduk (Ribu Jiwa) | C7: ='2. Data Penduduk'!B3 -> 158.77 | D7: ='2. Data Penduduk'!C3 -> 161.18 | E7: ='2. Data Penduduk'!D3 -> 163.56 | F7: ='2. Data Penduduk'!E3 -> 165.89 | G7: ='2. Data Penduduk'!F3 -> 168.19 | H7: ='2. Data Penduduk'!G3 -> 170.46
A8: Kabupaten Bintan | B8: PDRB per Kapita (Juta Rp) | C8: =C6/C7 -> 87.56163 | D8: =D6/D7 -> 86.446644 | E8: =E6/E7 -> 88.969002 | F8: =F6/F7 -> 93.105612 | G8: =G6/G7 -> 100.88347 | H8: =H6/H7 -> 107.28505
A10: Kabupaten Natuna | B10: Total PDRB (Miliar Rp) | C10: =SUMIF('1. Data PDRB ADHK'!$A$2:$A$120,$A10,'1. Data PDRB ADHK'!$E$2:$E$120) -> 12694.62 | D10: =SUMIF('1. Data PDRB ADHK'!$A$2:$A$120,$A10,'1. Data PDRB ADHK'!$F$2:$F$120) -> 12755.57 | E10: =SUMIF('1. Data PDRB ADHK'!$A$2:$A$120,$A10,'1. Data PDRB ADHK'!$G$2:$G$120) -> 13338.93 | F10: =SUMIF('1. Data PDRB ADHK'!$A$2:$A$120,$A10,'1. Data PDRB ADHK'!$H$2:$H$120) -> 14184.65 | G10: =SUMIF('1. Data PDRB ADHK'!$A$2:$A$120,$A10,'1. Data PDRB ADHK'!$I$2:$I$120) -> 14752.4 | H10: =SUMIF('1. Data PDRB ADHK'!$A$2:$A$120,$A10,'1. Data PDRB ADHK'!$J$2:$J$120) -> 15446.99
A11: Kabupaten Natuna | B11: Penduduk (Ribu Jiwa) | C11: ='2. Data Penduduk'!B4 -> 81.13 | D11: ='2. Data Penduduk'!C4 -> 82.28 | E11: ='2. Data Penduduk'!D4 -> 83.43 | F11: ='2. Data Penduduk'!E4 -> 84.56 | G11: ='2. Data Penduduk'!F4 -> 85.66 | H11: ='2. Data Penduduk'!G4 -> 86.76
A12: Kabupaten Natuna | B12: PDRB per Kapita (Juta Rp) | C12: =C10/C11 -> 156.47257 | D12: =D10/D11 -> 155.02637 | E12: =E10/E11 -> 159.8817 | F12: =F10/F11 -> 167.74657 | G12: =G10/G11 -> 172.22041 | H12: =H10/H11 -> 178.04276
A14: Kabupaten Lingga | B14: Total PDRB (Miliar Rp) | C14: =SUMIF('1. Data PDRB ADHK'!$A$2:$A$120,$A14,'1. Data PDRB ADHK'!$E$2:$E$120) -> 2912.6 | D14: =SUMIF('1. Data PDRB ADHK'!$A$2:$A$120,$A14,'1. Data PDRB ADHK'!$F$2:$F$120) -> 2971.59 | E14: =SUMIF('1. Data PDRB ADHK'!$A$2:$A$120,$A14,'1. Data PDRB ADHK'!$G$2:$G$120) -> 3082.81 | F14: =SUMIF('1. Data PDRB ADHK'!$A$2:$A$120,$A14,'1. Data PDRB ADHK'!$H$2:$H$120) -> 3215.39 | G14: =SUMIF('1. Data PDRB ADHK'!$A$2:$A$120,$A14,'1. Data PDRB ADHK'!$I$2:$I$120) -> 3357.6 | H14: =SUMIF('1. Data PDRB ADHK'!$A$2:$A$120,$A14,'1. Data PDRB ADHK'!$J$2:$J$120) -> 3527.78
A15: Kabupaten Lingga | B15: Penduduk (Ribu Jiwa) | C15: ='2. Data Penduduk'!B5 -> 97.99 | D15: ='2. Data Penduduk'!C5 -> 99.02 | E15: ='2. Data Penduduk'!D5 -> 100.03 | F15: ='2. Data Penduduk'!E5 -> 101.03 | G15: ='2. Data Penduduk'!F5 -> 102.01 | H15: ='2. Data Penduduk'!G5 -> 102.95
A16: Kabupaten Lingga | B16: PDRB per Kapita (Juta Rp) | C16: =C14/C15 -> 29.723441 | D16: =D14/D15 -> 30.009998 | E16: =E14/E15 -> 30.818854 | F16: =F14/F15 -> 31.826091 | G16: =G14/G15 -> 32.91442 | H16: =H14/H15 -> 34.266926
A18: Kabupaten Kepulauan Anambas | B18: Total PDRB (Miliar Rp) | C18: =SUMIF('1. Data PDRB ADHK'!$A$2:$A$120,$A18,'1. Data PDRB ADHK'!$E$2:$E$120) -> 11104.45 | D18: =SUMIF('1. Data PDRB ADHK'!$A$2:$A$120,$A18,'1. Data PDRB ADHK'!$F$2:$F$120) -> 11108.49 | E18: =SUMIF('1. Data PDRB ADHK'!$A$2:$A$120,$A18,'1. Data PDRB ADHK'!$G$2:$G$120) -> 11118.21 | F18: =SUMIF('1. Data PDRB ADHK'!$A$2:$A$120,$A18,'1. Data PDRB ADHK'!$H$2:$H$120) -> 11214.76 | G18: =SUMIF('1. Data PDRB ADHK'!$A$2:$A$120,$A18,'1. Data PDRB ADHK'!$I$2:$I$120) -> 11289.06 | H18: =SUMIF('1. Data PDRB ADHK'!$A$2:$A$120,$A18,'1. Data PDRB ADHK'!$J$2:$J$120) -> 11434.89
A19: Kabupaten Kepulauan Anambas | B19: Penduduk (Ribu Jiwa) | C19: ='2. Data Penduduk'!B6 -> 47.11 | D19: ='2. Data Penduduk'!C6 -> 47.78 | E19: ='2. Data Penduduk'!D6 -> 48.44 | F19: ='2. Data Penduduk'!E6 -> 49.09 | G19: ='2. Data Penduduk'!F6 -> 49.73 | H19: ='2. Data Penduduk'!G6 -> 50.36
A20: Kabupaten Kepulauan Anambas | B20: PDRB per Kapita (Juta Rp) | C20: =C18/C19 -> 235.71322 | D20: =D18/D19 -> 232.49247 | E20: =E18/E19 -> 229.52539 | F20: =F18/F19 -> 228.45305 | G20: =G18/G19 -> 227.00704 | H20: =H18/H19 -> 227.06295
A22: Kota Batam | B22: Total PDRB (Miliar Rp) | C22: =SUMIF('1. Data PDRB ADHK'!$A$2:$A$120,$A22,'1. Data PDRB ADHK'!$E$2:$E$120) -> 106027.64 | D22: =SUMIF('1. Data PDRB ADHK'!$A$2:$A$120,$A22,'1. Data PDRB ADHK'!$F$2:$F$120) -> 111068.93 | E22: =SUMIF('1. Data PDRB ADHK'!$A$2:$A$120,$A22,'1. Data PDRB ADHK'!$G$2:$G$120) -> 118665.19 | F22: =SUMIF('1. Data PDRB ADHK'!$A$2:$A$120,$A22,'1. Data PDRB ADHK'!$H$2:$H$120) -> 127132.38 | G22: =SUMIF('1. Data PDRB ADHK'!$A$2:$A$120,$A22,'1. Data PDRB ADHK'!$I$2:$I$120) -> 137219.01 | H22: =SUMIF('1. Data PDRB ADHK'!$A$2:$A$120,$A22,'1. Data PDRB ADHK'!$J$2:$J$120) -> 145856.31
A23: Kota Batam | B23: Penduduk (Ribu Jiwa) | C23: ='2. Data Penduduk'!B7 -> 1193.96 | D23: ='2. Data Penduduk'!C7 -> 1215.14 | E23: ='2. Data Penduduk'!D7 -> 1236.01 | F23: ='2. Data Penduduk'!E7 -> 1256.61 | G23: ='2. Data Penduduk'!F7 -> 1276.93 | H23: ='2. Data Penduduk'!G7 -> 1296.96
A24: Kota Batam | B24: PDRB per Kapita (Juta Rp) | C24: =C22/C23 -> 88.803343 | D24: =D22/D23 -> 91.404225 | E24: =E22/E23 -> 96.006659 | F24: =F22/F23 -> 101.17091 | G24: =G22/G23 -> 107.46009 | H24: =H22/H23 -> 112.46015
A26: Kota Tanjungpinang | B26: Total PDRB (Miliar Rp) | C26: =SUMIF('1. Data PDRB ADHK'!$A$2:$A$120,$A26,'1. Data PDRB ADHK'!$E$2:$E$120) -> 13938.22 | D26: =SUMIF('1. Data PDRB ADHK'!$A$2:$A$120,$A26,'1. Data PDRB ADHK'!$F$2:$F$120) -> 14020.21 | E26: =SUMIF('1. Data PDRB ADHK'!$A$2:$A$120,$A26,'1. Data PDRB ADHK'!$G$2:$G$120) -> 14597.58 | F26: =SUMIF('1. Data PDRB ADHK'!$A$2:$A$120,$A26,'1. Data PDRB ADHK'!$H$2:$H$120) -> 15316 | G26: =SUMIF('1. Data PDRB ADHK'!$A$2:$A$120,$A26,'1. Data PDRB ADHK'!$I$2:$I$120) -> 15894.74 | H26: =SUMIF('1. Data PDRB ADHK'!$A$2:$A$120,$A26,'1. Data PDRB ADHK'!$J$2:$J$120) -> 16679.07
A27: Kota Tanjungpinang | B27: Penduduk (Ribu Jiwa) | C27: ='2. Data Penduduk'!B8 -> 226.81 | D27: ='2. Data Penduduk'!C8 -> 229.54 | E27: ='2. Data Penduduk'!D8 -> 232.2 | F27: ='2. Data Penduduk'!E8 -> 234.84 | G27: ='2. Data Penduduk'!F8 -> 237.43 | H27: ='2. Data Penduduk'!G8 -> 239.96
A28: Kota Tanjungpinang | B28: PDRB per Kapita (Juta Rp) | C28: =C26/C27 -> 61.453287 | D28: =D26/D27 -> 61.079594 | E28: =E26/E27 -> 62.866408 | F28: =F26/F27 -> 65.218872 | G28: =G26/G27 -> 66.944952 | H28: =H26/H27 -> 69.50771
A30: Provinsi Kepulauan Riau | B30: Total PDRB (Miliar Rp) | C30: =C2+C6+C10+C14+C18+C22+C26 -> 169696.8 | D30: =D2+D6+D10+D14+D18+D22+D26 -> 175191.03 | E30: =E2+E6+E10+E14+E18+E22+E26 -> 185096.35 | F30: =F2+F6+F10+F14+F18+F22+F26 -> 196786.07 | G30: =G2+G6+G10+G14+G18+G22+G26 -> 210553.98 | H30: =H2+H6+H10+H14+H18+H22+H26 -> 222971.83
A31: Provinsi Kepulauan Riau | B31: Penduduk (Ribu Jiwa) | C31: ='2. Data Penduduk'!B9 -> 2057.86 | D31: ='2. Data Penduduk'!C9 -> 2089.89 | E31: ='2. Data Penduduk'!D9 -> 2121.48 | F31: ='2. Data Penduduk'!E9 -> 2152.63 | G31: ='2. Data Penduduk'!F9 -> 2183.29 | H31: ='2. Data Penduduk'!G9 -> 2213.46
A32: Provinsi Kepulauan Riau | B32: PDRB per Kapita (Juta Rp) | C32: =C30/C31 -> 82.462753 | D32: =D30/D31 -> 83.827871 | E32: =E30/E31 -> 87.24869 | F32: =F30/F31 -> 91.416579 | G32: =G30/G31 -> 96.438851 | H32: =H30/H31 -> 100.73452

Sheet 4. Laju Pertumbuhan
A1: Kabupaten/Kota | B1: 2021 | C1: 2022 | D1: 2023 | E1: 2024 | F1: 2025
A2: Kabupaten Karimun | B2: =('3. Total PDRB & Per Kapita'!D2-'3. Total PDRB & Per Kapita'!C2)/'3. Total PDRB & Per Kapita'!C2 -> 0.023654426 | C2: =('3. Total PDRB & Per Kapita'!E2-'3. Total PDRB & Per Kapita'!D2)/'3. Total PDRB & Per Kapita'!D2 -> 0.043833717 | D2: =('3. Total PDRB & Per Kapita'!F2-'3. Total PDRB & Per Kapita'!E2)/'3. Total PDRB & Per Kapita'!E2 -> 0.054993605 | E2: =('3. Total PDRB & Per Kapita'!G2-'3. Total PDRB & Per Kapita'!F2)/'3. Total PDRB & Per Kapita'!F2 -> 0.077448042 | F2: =('3. Total PDRB & Per Kapita'!H2-'3. Total PDRB & Per Kapita'!G2)/'3. Total PDRB & Per Kapita'!G2 -> 0.060088969
A3: Kabupaten Bintan | B3: =('3. Total PDRB & Per Kapita'!D6-'3. Total PDRB & Per Kapita'!C6)/'3. Total PDRB & Per Kapita'!C6 -> 0.002252168 | C3: =('3. Total PDRB & Per Kapita'!E6-'3. Total PDRB & Per Kapita'!D6)/'3. Total PDRB & Per Kapita'!D6 -> 0.044375163 | D3: =('3. Total PDRB & Per Kapita'!F6-'3. Total PDRB & Per Kapita'!E6)/'3. Total PDRB & Per Kapita'!E6 -> 0.06140284 | E3: =('3. Total PDRB & Per Kapita'!G6-'3. Total PDRB & Per Kapita'!F6)/'3. Total PDRB & Per Kapita'!F6 -> 0.098560791 | F3: =('3. Total PDRB & Per Kapita'!H6-'3. Total PDRB & Per Kapita'!G6)/'3. Total PDRB & Per Kapita'!G6 -> 0.077808339
A4: Kabupaten Natuna | B4: =('3. Total PDRB & Per Kapita'!D10-'3. Total PDRB & Per Kapita'!C10)/'3. Total PDRB & Per Kapita'!C10 -> 0.0048012465 | C4: =('3. Total PDRB & Per Kapita'!E10-'3. Total PDRB & Per Kapita'!D10)/'3. Total PDRB & Per Kapita'!D10 -> 0.045733746 | D4: =('3. Total PDRB & Per Kapita'!F10-'3. Total PDRB & Per Kapita'!E10)/'3. Total PDRB & Per Kapita'!E10 -> 0.063402387 | E4: =('3. Total PDRB & Per Kapita'!G10-'3. Total PDRB & Per Kapita'!F10)/'3. Total PDRB & Per Kapita'!F10 -> 0.040025662 | F4: =('3. Total PDRB & Per Kapita'!H10-'3. Total PDRB & Per Kapita'!G10)/'3. Total PDRB & Per Kapita'!G10 -> 0.047083186
A5: Kabupaten Lingga | B5: =('3. Total PDRB & Per Kapita'!D14-'3. Total PDRB & Per Kapita'!C14)/'3. Total PDRB & Per Kapita'!C14 -> 0.020253382 | C5: =('3. Total PDRB & Per Kapita'!E14-'3. Total PDRB & Per Kapita'!D14)/'3. Total PDRB & Per Kapita'!D14 -> 0.037427774 | D5: =('3. Total PDRB & Per Kapita'!F14-'3. Total PDRB & Per Kapita'!E14)/'3. Total PDRB & Per Kapita'!E14 -> 0.043006218 | E5: =('3. Total PDRB & Per Kapita'!G14-'3. Total PDRB & Per Kapita'!F14)/'3. Total PDRB & Per Kapita'!F14 -> 0.044227916 | F5: =('3. Total PDRB & Per Kapita'!H14-'3. Total PDRB & Per Kapita'!G14)/'3. Total PDRB & Per Kapita'!G14 -> 0.050685013
A6: Kabupaten Kepulauan Anambas | B6: =('3. Total PDRB & Per Kapita'!D18-'3. Total PDRB & Per Kapita'!C18)/'3. Total PDRB & Per Kapita'!C18 -> 0.00036381811 | C6: =('3. Total PDRB & Per Kapita'!E18-'3. Total PDRB & Per Kapita'!D18)/'3. Total PDRB & Per Kapita'!D18 -> 0.00087500641 | D6: =('3. Total PDRB & Per Kapita'!F18-'3. Total PDRB & Per Kapita'!E18)/'3. Total PDRB & Per Kapita'!E18 -> 0.0086839518 | E6: =('3. Total PDRB & Per Kapita'!G18-'3. Total PDRB & Per Kapita'!F18)/'3. Total PDRB & Per Kapita'!F18 -> 0.0066251975 | F6: =('3. Total PDRB & Per Kapita'!H18-'3. Total PDRB & Per Kapita'!G18)/'3. Total PDRB & Per Kapita'!G18 -> 0.012917816
A7: Kota Batam | B7: =('3. Total PDRB & Per Kapita'!D22-'3. Total PDRB & Per Kapita'!C22)/'3. Total PDRB & Per Kapita'!C22 -> 0.047546942 | C7: =('3. Total PDRB & Per Kapita'!E22-'3. Total PDRB & Per Kapita'!D22)/'3. Total PDRB & Per Kapita'!D22 -> 0.068392304 | D7: =('3. Total PDRB & Per Kapita'!F22-'3. Total PDRB & Per Kapita'!E22)/'3. Total PDRB & Per Kapita'!E22 -> 0.071353613 | E7: =('3. Total PDRB & Per Kapita'!G22-'3. Total PDRB & Per Kapita'!F22)/'3. Total PDRB & Per Kapita'!F22 -> 0.079339583 | F7: =('3. Total PDRB & Per Kapita'!H22-'3. Total PDRB & Per Kapita'!G22)/'3. Total PDRB & Per Kapita'!G22 -> 0.06294536
A8: Kota Tanjungpinang | B8: =('3. Total PDRB & Per Kapita'!D26-'3. Total PDRB & Per Kapita'!C26)/'3. Total PDRB & Per Kapita'!C26 -> 0.0058823867 | C8: =('3. Total PDRB & Per Kapita'!E26-'3. Total PDRB & Per Kapita'!D26)/'3. Total PDRB & Per Kapita'!D26 -> 0.041181266 | D8: =('3. Total PDRB & Per Kapita'!F26-'3. Total PDRB & Per Kapita'!E26)/'3. Total PDRB & Per Kapita'!E26 -> 0.049215007 | E8: =('3. Total PDRB & Per Kapita'!G26-'3. Total PDRB & Per Kapita'!F26)/'3. Total PDRB & Per Kapita'!F26 -> 0.037786628 | F8: =('3. Total PDRB & Per Kapita'!H26-'3. Total PDRB & Per Kapita'!G26)/'3. Total PDRB & Per Kapita'!G26 -> 0.049345255
A9: Provinsi Kepulauan Riau | B9: =('3. Total PDRB & Per Kapita'!D30-'3. Total PDRB & Per Kapita'!C30)/'3. Total PDRB & Per Kapita'!C30 -> 0.032376745 | C9: =('3. Total PDRB & Per Kapita'!E30-'3. Total PDRB & Per Kapita'!D30)/'3. Total PDRB & Per Kapita'!D30 -> 0.056540109 | D9: =('3. Total PDRB & Per Kapita'!F30-'3. Total PDRB & Per Kapita'!E30)/'3. Total PDRB & Per Kapita'!E30 -> 0.063154784 | E9: =('3. Total PDRB & Per Kapita'!G30-'3. Total PDRB & Per Kapita'!F30)/'3. Total PDRB & Per Kapita'!F30 -> 0.069963844 | F9: =('3. Total PDRB & Per Kapita'!H30-'3. Total PDRB & Per Kapita'!G30)/'3. Total PDRB & Per Kapita'!G30 -> 0.058977038
A11: Laju Pertumbuhan(t) = (PDRB ADHK(t) - PDRB ADHK(t-1)) / PDRB ADHK(t-1). 2020 tidak punya nilai growth (tidak ada data 2019 sebagai basis).

Sheet 5. Tipologi Klassen
A1: Kabupaten/Kota | B1: Tahun | C1: PDRB per Kapita (Juta Rp) | D1: Pertumbuhan Ekonomi (%) | E1: PDRB per Kapita Provinsi (Juta Rp) | F1: Pertumbuhan Provinsi (%) | G1: Kategori Per Kapita | H1: Kategori Pertumbuhan | I1: KUADRAN
A2: Kabupaten Karimun | B2: 2021 | C2: ='3. Total PDRB & Per Kapita'!D4 -> 36.60484 | D2: ='4. Laju Pertumbuhan'!B2 -> 0.023654426 | E2: ='3. Total PDRB & Per Kapita'!D32 -> 83.827871 | F2: ='4. Laju Pertumbuhan'!B9 -> 0.032376745 | G2: =IF(C2>=E2,"Tinggi","Rendah") -> Rendah | H2: =IF(D2>=F2,"Tinggi","Rendah") -> Rendah | I2: =IF(AND(G2="Tinggi",H2="Tinggi"),"I - Maju & Tumbuh Cepat",IF(AND(G2="Tinggi",H2="Rendah"),"II - Maju tapi Tertekan",IF(AND(G2="Rendah",H2="Rendah"),"III - Relatif Tertinggal","IV - Berkembang Cepat"))) -> III - Relatif Tertinggal
A3: Kabupaten Karimun | B3: 2022 | C3: ='3. Total PDRB & Per Kapita'!E4 -> 37.788441 | D3: ='4. Laju Pertumbuhan'!C2 -> 0.043833717 | E3: ='3. Total PDRB & Per Kapita'!E32 -> 87.24869 | F3: ='4. Laju Pertumbuhan'!C9 -> 0.056540109 | G3: =IF(C3>=E3,"Tinggi","Rendah") -> Rendah | H3: =IF(D3>=F3,"Tinggi","Rendah") -> Rendah | I3: =IF(AND(G3="Tinggi",H3="Tinggi"),"I - Maju & Tumbuh Cepat",IF(AND(G3="Tinggi",H3="Rendah"),"II - Maju tapi Tertekan",IF(AND(G3="Rendah",H3="Rendah"),"III - Relatif Tertinggal","IV - Berkembang Cepat"))) -> III - Relatif Tertinggal
A4: Kabupaten Karimun | B4: 2023 | C4: ='3. Total PDRB & Per Kapita'!F4 -> 39.438219 | D4: ='4. Laju Pertumbuhan'!D2 -> 0.054993605 | E4: ='3. Total PDRB & Per Kapita'!F32 -> 91.416579 | F4: ='4. Laju Pertumbuhan'!D9 -> 0.063154784 | G4: =IF(C4>=E4,"Tinggi","Rendah") -> Rendah | H4: =IF(D4>=F4,"Tinggi","Rendah") -> Rendah | I4: =IF(AND(G4="Tinggi",H4="Tinggi"),"I - Maju & Tumbuh Cepat",IF(AND(G4="Tinggi",H4="Rendah"),"II - Maju tapi Tertekan",IF(AND(G4="Rendah",H4="Rendah"),"III - Relatif Tertinggal","IV - Berkembang Cepat"))) -> III - Relatif Tertinggal
A5: Kabupaten Karimun | B5: 2024 | C5: ='3. Total PDRB & Per Kapita'!G4 -> 42.050505 | D5: ='4. Laju Pertumbuhan'!E2 -> 0.077448042 | E5: ='3. Total PDRB & Per Kapita'!G32 -> 96.438851 | F5: ='4. Laju Pertumbuhan'!E9 -> 0.069963844 | G5: =IF(C5>=E5,"Tinggi","Rendah") -> Rendah | H5: =IF(D5>=F5,"Tinggi","Rendah") -> Tinggi | I5: =IF(AND(G5="Tinggi",H5="Tinggi"),"I - Maju & Tumbuh Cepat",IF(AND(G5="Tinggi",H5="Rendah"),"II - Maju tapi Tertekan",IF(AND(G5="Rendah",H5="Rendah"),"III - Relatif Tertinggal","IV - Berkembang Cepat"))) -> IV - Berkembang Cepat
A6: Kabupaten Karimun | B6: 2025 | C6: ='3. Total PDRB & Per Kapita'!H4 -> 44.129845 | D6: ='4. Laju Pertumbuhan'!F2 -> 0.060088969 | E6: ='3. Total PDRB & Per Kapita'!H32 -> 100.73452 | F6: ='4. Laju Pertumbuhan'!F9 -> 0.058977038 | G6: =IF(C6>=E6,"Tinggi","Rendah") -> Rendah | H6: =IF(D6>=F6,"Tinggi","Rendah") -> Tinggi | I6: =IF(AND(G6="Tinggi",H6="Tinggi"),"I - Maju & Tumbuh Cepat",IF(AND(G6="Tinggi",H6="Rendah"),"II - Maju tapi Tertekan",IF(AND(G6="Rendah",H6="Rendah"),"III - Relatif Tertinggal","IV - Berkembang Cepat"))) -> IV - Berkembang Cepat
A7: Kabupaten Bintan | B7: 2021 | C7: ='3. Total PDRB & Per Kapita'!D8 -> 86.446644 | D7: ='4. Laju Pertumbuhan'!B3 -> 0.002252168 | E7: ='3. Total PDRB & Per Kapita'!D32 -> 83.827871 | F7: ='4. Laju Pertumbuhan'!B9 -> 0.032376745 | G7: =IF(C7>=E7,"Tinggi","Rendah") -> Tinggi | H7: =IF(D7>=F7,"Tinggi","Rendah") -> Rendah | I7: =IF(AND(G7="Tinggi",H7="Tinggi"),"I - Maju & Tumbuh Cepat",IF(AND(G7="Tinggi",H7="Rendah"),"II - Maju tapi Tertekan",IF(AND(G7="Rendah",H7="Rendah"),"III - Relatif Tertinggal","IV - Berkembang Cepat"))) -> II - Maju tapi Tertekan
A8: Kabupaten Bintan | B8: 2022 | C8: ='3. Total PDRB & Per Kapita'!E8 -> 88.969002 | D8: ='4. Laju Pertumbuhan'!C3 -> 0.044375163 | E8: ='3. Total PDRB & Per Kapita'!E32 -> 87.24869 | F8: ='4. Laju Pertumbuhan'!C9 -> 0.056540109 | G8: =IF(C8>=E8,"Tinggi","Rendah") -> Tinggi | H8: =IF(D8>=F8,"Tinggi","Rendah") -> Rendah | I8: =IF(AND(G8="Tinggi",H8="Tinggi"),"I - Maju & Tumbuh Cepat",IF(AND(G8="Tinggi",H8="Rendah"),"II - Maju tapi Tertekan",IF(AND(G8="Rendah",H8="Rendah"),"III - Relatif Tertinggal","IV - Berkembang Cepat"))) -> II - Maju tapi Tertekan
A9: Kabupaten Bintan | B9: 2023 | C9: ='3. Total PDRB & Per Kapita'!F8 -> 93.105612 | D9: ='4. Laju Pertumbuhan'!D3 -> 0.06140284 | E9: ='3. Total PDRB & Per Kapita'!F32 -> 91.416579 | F9: ='4. Laju Pertumbuhan'!D9 -> 0.063154784 | G9: =IF(C9>=E9,"Tinggi","Rendah") -> Tinggi | H9: =IF(D9>=F9,"Tinggi","Rendah") -> Rendah | I9: =IF(AND(G9="Tinggi",H9="Tinggi"),"I - Maju & Tumbuh Cepat",IF(AND(G9="Tinggi",H9="Rendah"),"II - Maju tapi Tertekan",IF(AND(G9="Rendah",H9="Rendah"),"III - Relatif Tertinggal","IV - Berkembang Cepat"))) -> II - Maju tapi Tertekan
A10: Kabupaten Bintan | B10: 2024 | C10: ='3. Total PDRB & Per Kapita'!G8 -> 100.88347 | D10: ='4. Laju Pertumbuhan'!E3 -> 0.098560791 | E10: ='3. Total PDRB & Per Kapita'!G32 -> 96.438851 | F10: ='4. Laju Pertumbuhan'!E9 -> 0.069963844 | G10: =IF(C10>=E10,"Tinggi","Rendah") -> Tinggi | H10: =IF(D10>=F10,"Tinggi","Rendah") -> Tinggi | I10: =IF(AND(G10="Tinggi",H10="Tinggi"),"I - Maju & Tumbuh Cepat",IF(AND(G10="Tinggi",H10="Rendah"),"II - Maju tapi Tertekan",IF(AND(G10="Rendah",H10="Rendah"),"III - Relatif Tertinggal","IV - Berkembang Cepat"))) -> I - Maju & Tumbuh Cepat
A11: Kabupaten Bintan | B11: 2025 | C11: ='3. Total PDRB & Per Kapita'!H8 -> 107.28505 | D11: ='4. Laju Pertumbuhan'!F3 -> 0.077808339 | E11: ='3. Total PDRB & Per Kapita'!H32 -> 100.73452 | F11: ='4. Laju Pertumbuhan'!F9 -> 0.058977038 | G11: =IF(C11>=E11,"Tinggi","Rendah") -> Tinggi | H11: =IF(D11>=F11,"Tinggi","Rendah") -> Tinggi | I11: =IF(AND(G11="Tinggi",H11="Tinggi"),"I - Maju & Tumbuh Cepat",IF(AND(G11="Tinggi",H11="Rendah"),"II - Maju tapi Tertekan",IF(AND(G11="Rendah",H11="Rendah"),"III - Relatif Tertinggal","IV - Berkembang Cepat"))) -> I - Maju & Tumbuh Cepat
A12: Kabupaten Natuna | B12: 2021 | C12: ='3. Total PDRB & Per Kapita'!D12 -> 155.02637 | D12: ='4. Laju Pertumbuhan'!B4 -> 0.0048012465 | E12: ='3. Total PDRB & Per Kapita'!D32 -> 83.827871 | F12: ='4. Laju Pertumbuhan'!B9 -> 0.032376745 | G12: =IF(C12>=E12,"Tinggi","Rendah") -> Tinggi | H12: =IF(D12>=F12,"Tinggi","Rendah") -> Rendah | I12: =IF(AND(G12="Tinggi",H12="Tinggi"),"I - Maju & Tumbuh Cepat",IF(AND(G12="Tinggi",H12="Rendah"),"II - Maju tapi Tertekan",IF(AND(G12="Rendah",H12="Rendah"),"III - Relatif Tertinggal","IV - Berkembang Cepat"))) -> II - Maju tapi Tertekan
A13: Kabupaten Natuna | B13: 2022 | C13: ='3. Total PDRB & Per Kapita'!E12 -> 159.8817 | D13: ='4. Laju Pertumbuhan'!C4 -> 0.045733746 | E13: ='3. Total PDRB & Per Kapita'!E32 -> 87.24869 | F13: ='4. Laju Pertumbuhan'!C9 -> 0.056540109 | G13: =IF(C13>=E13,"Tinggi","Rendah") -> Tinggi | H13: =IF(D13>=F13,"Tinggi","Rendah") -> Rendah | I13: =IF(AND(G13="Tinggi",H13="Tinggi"),"I - Maju & Tumbuh Cepat",IF(AND(G13="Tinggi",H13="Rendah"),"II - Maju tapi Tertekan",IF(AND(G13="Rendah",H13="Rendah"),"III - Relatif Tertinggal","IV - Berkembang Cepat"))) -> II - Maju tapi Tertekan
A14: Kabupaten Natuna | B14: 2023 | C14: ='3. Total PDRB & Per Kapita'!F12 -> 167.74657 | D14: ='4. Laju Pertumbuhan'!D4 -> 0.063402387 | E14: ='3. Total PDRB & Per Kapita'!F32 -> 91.416579 | F14: ='4. Laju Pertumbuhan'!D9 -> 0.063154784 | G14: =IF(C14>=E14,"Tinggi","Rendah") -> Tinggi | H14: =IF(D14>=F14,"Tinggi","Rendah") -> Tinggi | I14: =IF(AND(G14="Tinggi",H14="Tinggi"),"I - Maju & Tumbuh Cepat",IF(AND(G14="Tinggi",H14="Rendah"),"II - Maju tapi Tertekan",IF(AND(G14="Rendah",H14="Rendah"),"III - Relatif Tertinggal","IV - Berkembang Cepat"))) -> I - Maju & Tumbuh Cepat
A15: Kabupaten Natuna | B15: 2024 | C15: ='3. Total PDRB & Per Kapita'!G12 -> 172.22041 | D15: ='4. Laju Pertumbuhan'!E4 -> 0.040025662 | E15: ='3. Total PDRB & Per Kapita'!G32 -> 96.438851 | F15: ='4. Laju Pertumbuhan'!E9 -> 0.069963844 | G15: =IF(C15>=E15,"Tinggi","Rendah") -> Tinggi | H15: =IF(D15>=F15,"Tinggi","Rendah") -> Rendah | I15: =IF(AND(G15="Tinggi",H15="Tinggi"),"I - Maju & Tumbuh Cepat",IF(AND(G15="Tinggi",H15="Rendah"),"II - Maju tapi Tertekan",IF(AND(G15="Rendah",H15="Rendah"),"III - Relatif Tertinggal","IV - Berkembang Cepat"))) -> II - Maju tapi Tertekan
A16: Kabupaten Natuna | B16: 2025 | C16: ='3. Total PDRB & Per Kapita'!H12 -> 178.04276 | D16: ='4. Laju Pertumbuhan'!F4 -> 0.047083186 | E16: ='3. Total PDRB & Per Kapita'!H32 -> 100.73452 | F16: ='4. Laju Pertumbuhan'!F9 -> 0.058977038 | G16: =IF(C16>=E16,"Tinggi","Rendah") -> Tinggi | H16: =IF(D16>=F16,"Tinggi","Rendah") -> Rendah | I16: =IF(AND(G16="Tinggi",H16="Tinggi"),"I - Maju & Tumbuh Cepat",IF(AND(G16="Tinggi",H16="Rendah"),"II - Maju tapi Tertekan",IF(AND(G16="Rendah",H16="Rendah"),"III - Relatif Tertinggal","IV - Berkembang Cepat"))) -> II - Maju tapi Tertekan
A17: Kabupaten Lingga | B17: 2021 | C17: ='3. Total PDRB & Per Kapita'!D16 -> 30.009998 | D17: ='4. Laju Pertumbuhan'!B5 -> 0.020253382 | E17: ='3. Total PDRB & Per Kapita'!D32 -> 83.827871 | F17: ='4. Laju Pertumbuhan'!B9 -> 0.032376745 | G17: =IF(C17>=E17,"Tinggi","Rendah") -> Rendah | H17: =IF(D17>=F17,"Tinggi","Rendah") -> Rendah | I17: =IF(AND(G17="Tinggi",H17="Tinggi"),"I - Maju & Tumbuh Cepat",IF(AND(G17="Tinggi",H17="Rendah"),"II - Maju tapi Tertekan",IF(AND(G17="Rendah",H17="Rendah"),"III - Relatif Tertinggal","IV - Berkembang Cepat"))) -> III - Relatif Tertinggal
A18: Kabupaten Lingga | B18: 2022 | C18: ='3. Total PDRB & Per Kapita'!E16 -> 30.818854 | D18: ='4. Laju Pertumbuhan'!C5 -> 0.037427774 | E18: ='3. Total PDRB & Per Kapita'!E32 -> 87.24869 | F18: ='4. Laju Pertumbuhan'!C9 -> 0.056540109 | G18: =IF(C18>=E18,"Tinggi","Rendah") -> Rendah | H18: =IF(D18>=F18,"Tinggi","Rendah") -> Rendah | I18: =IF(AND(G18="Tinggi",H18="Tinggi"),"I - Maju & Tumbuh Cepat",IF(AND(G18="Tinggi",H18="Rendah"),"II - Maju tapi Tertekan",IF(AND(G18="Rendah",H18="Rendah"),"III - Relatif Tertinggal","IV - Berkembang Cepat"))) -> III - Relatif Tertinggal
A19: Kabupaten Lingga | B19: 2023 | C19: ='3. Total PDRB & Per Kapita'!F16 -> 31.826091 | D19: ='4. Laju Pertumbuhan'!D5 -> 0.043006218 | E19: ='3. Total PDRB & Per Kapita'!F32 -> 91.416579 | F19: ='4. Laju Pertumbuhan'!D9 -> 0.063154784 | G19: =IF(C19>=E19,"Tinggi","Rendah") -> Rendah | H19: =IF(D19>=F19,"Tinggi","Rendah") -> Rendah | I19: =IF(AND(G19="Tinggi",H19="Tinggi"),"I - Maju & Tumbuh Cepat",IF(AND(G19="Tinggi",H19="Rendah"),"II - Maju tapi Tertekan",IF(AND(G19="Rendah",H19="Rendah"),"III - Relatif Tertinggal","IV - Berkembang Cepat"))) -> III - Relatif Tertinggal
A20: Kabupaten Lingga | B20: 2024 | C20: ='3. Total PDRB & Per Kapita'!G16 -> 32.91442 | D20: ='4. Laju Pertumbuhan'!E5 -> 0.044227916 | E20: ='3. Total PDRB & Per Kapita'!G32 -> 96.438851 | F20: ='4. Laju Pertumbuhan'!E9 -> 0.069963844 | G20: =IF(C20>=E20,"Tinggi","Rendah") -> Rendah | H20: =IF(D20>=F20,"Tinggi","Rendah") -> Rendah | I20: =IF(AND(G20="Tinggi",H20="Tinggi"),"I - Maju & Tumbuh Cepat",IF(AND(G20="Tinggi",H20="Rendah"),"II - Maju tapi Tertekan",IF(AND(G20="Rendah",H20="Rendah"),"III - Relatif Tertinggal","IV - Berkembang Cepat"))) -> III - Relatif Tertinggal
A21: Kabupaten Lingga | B21: 2025 | C21: ='3. Total PDRB & Per Kapita'!H16 -> 34.266926 | D21: ='4. Laju Pertumbuhan'!F5 -> 0.050685013 | E21: ='3. Total PDRB & Per Kapita'!H32 -> 100.73452 | F21: ='4. Laju Pertumbuhan'!F9 -> 0.058977038 | G21: =IF(C21>=E21,"Tinggi","Rendah") -> Rendah | H21: =IF(D21>=F21,"Tinggi","Rendah") -> Rendah | I21: =IF(AND(G21="Tinggi",H21="Tinggi"),"I - Maju & Tumbuh Cepat",IF(AND(G21="Tinggi",H21="Rendah"),"II - Maju tapi Tertekan",IF(AND(G21="Rendah",H21="Rendah"),"III - Relatif Tertinggal","IV - Berkembang Cepat"))) -> III - Relatif Tertinggal
A22: Kabupaten Kepulauan Anambas | B22: 2021 | C22: ='3. Total PDRB & Per Kapita'!D20 -> 232.49247 | D22: ='4. Laju Pertumbuhan'!B6 -> 0.00036381811 | E22: ='3. Total PDRB & Per Kapita'!D32 -> 83.827871 | F22: ='4. Laju Pertumbuhan'!B9 -> 0.032376745 | G22: =IF(C22>=E22,"Tinggi","Rendah") -> Tinggi | H22: =IF(D22>=F22,"Tinggi","Rendah") -> Rendah | I22: =IF(AND(G22="Tinggi",H22="Tinggi"),"I - Maju & Tumbuh Cepat",IF(AND(G22="Tinggi",H22="Rendah"),"II - Maju tapi Tertekan",IF(AND(G22="Rendah",H22="Rendah"),"III - Relatif Tertinggal","IV - Berkembang Cepat"))) -> II - Maju tapi Tertekan
A23: Kabupaten Kepulauan Anambas | B23: 2022 | C23: ='3. Total PDRB & Per Kapita'!E20 -> 229.52539 | D23: ='4. Laju Pertumbuhan'!C6 -> 0.00087500641 | E23: ='3. Total PDRB & Per Kapita'!E32 -> 87.24869 | F23: ='4. Laju Pertumbuhan'!C9 -> 0.056540109 | G23: =IF(C23>=E23,"Tinggi","Rendah") -> Tinggi | H23: =IF(D23>=F23,"Tinggi","Rendah") -> Rendah | I23: =IF(AND(G23="Tinggi",H23="Tinggi"),"I - Maju & Tumbuh Cepat",IF(AND(G23="Tinggi",H23="Rendah"),"II - Maju tapi Tertekan",IF(AND(G23="Rendah",H23="Rendah"),"III - Relatif Tertinggal","IV - Berkembang Cepat"))) -> II - Maju tapi Tertekan
A24: Kabupaten Kepulauan Anambas | B24: 2023 | C24: ='3. Total PDRB & Per Kapita'!F20 -> 228.45305 | D24: ='4. Laju Pertumbuhan'!D6 -> 0.0086839518 | E24: ='3. Total PDRB & Per Kapita'!F32 -> 91.416579 | F24: ='4. Laju Pertumbuhan'!D9 -> 0.063154784 | G24: =IF(C24>=E24,"Tinggi","Rendah") -> Tinggi | H24: =IF(D24>=F24,"Tinggi","Rendah") -> Rendah | I24: =IF(AND(G24="Tinggi",H24="Tinggi"),"I - Maju & Tumbuh Cepat",IF(AND(G24="Tinggi",H24="Rendah"),"II - Maju tapi Tertekan",IF(AND(G24="Rendah",H24="Rendah"),"III - Relatif Tertinggal","IV - Berkembang Cepat"))) -> II - Maju tapi Tertekan
A25: Kabupaten Kepulauan Anambas | B25: 2024 | C25: ='3. Total PDRB & Per Kapita'!G20 -> 227.00704 | D25: ='4. Laju Pertumbuhan'!E6 -> 0.0066251975 | E25: ='3. Total PDRB & Per Kapita'!G32 -> 96.438851 | F25: ='4. Laju Pertumbuhan'!E9 -> 0.069963844 | G25: =IF(C25>=E25,"Tinggi","Rendah") -> Tinggi | H25: =IF(D25>=F25,"Tinggi","Rendah") -> Rendah | I25: =IF(AND(G25="Tinggi",H25="Tinggi"),"I - Maju & Tumbuh Cepat",IF(AND(G25="Tinggi",H25="Rendah"),"II - Maju tapi Tertekan",IF(AND(G25="Rendah",H25="Rendah"),"III - Relatif Tertinggal","IV - Berkembang Cepat"))) -> II - Maju tapi Tertekan
A26: Kabupaten Kepulauan Anambas | B26: 2025 | C26: ='3. Total PDRB & Per Kapita'!H20 -> 227.06295 | D26: ='4. Laju Pertumbuhan'!F6 -> 0.012917816 | E26: ='3. Total PDRB & Per Kapita'!H32 -> 100.73452 | F26: ='4. Laju Pertumbuhan'!F9 -> 0.058977038 | G26: =IF(C26>=E26,"Tinggi","Rendah") -> Tinggi | H26: =IF(D26>=F26,"Tinggi","Rendah") -> Rendah | I26: =IF(AND(G26="Tinggi",H26="Tinggi"),"I - Maju & Tumbuh Cepat",IF(AND(G26="Tinggi",H26="Rendah"),"II - Maju tapi Tertekan",IF(AND(G26="Rendah",H26="Rendah"),"III - Relatif Tertinggal","IV - Berkembang Cepat"))) -> II - Maju tapi Tertekan
A27: Kota Batam | B27: 2021 | C27: ='3. Total PDRB & Per Kapita'!D24 -> 91.404225 | D27: ='4. Laju Pertumbuhan'!B7 -> 0.047546942 | E27: ='3. Total PDRB & Per Kapita'!D32 -> 83.827871 | F27: ='4. Laju Pertumbuhan'!B9 -> 0.032376745 | G27: =IF(C27>=E27,"Tinggi","Rendah") -> Tinggi | H27: =IF(D27>=F27,"Tinggi","Rendah") -> Tinggi | I27: =IF(AND(G27="Tinggi",H27="Tinggi"),"I - Maju & Tumbuh Cepat",IF(AND(G27="Tinggi",H27="Rendah"),"II - Maju tapi Tertekan",IF(AND(G27="Rendah",H27="Rendah"),"III - Relatif Tertinggal","IV - Berkembang Cepat"))) -> I - Maju & Tumbuh Cepat
A28: Kota Batam | B28: 2022 | C28: ='3. Total PDRB & Per Kapita'!E24 -> 96.006659 | D28: ='4. Laju Pertumbuhan'!C7 -> 0.068392304 | E28: ='3. Total PDRB & Per Kapita'!E32 -> 87.24869 | F28: ='4. Laju Pertumbuhan'!C9 -> 0.056540109 | G28: =IF(C28>=E28,"Tinggi","Rendah") -> Tinggi | H28: =IF(D28>=F28,"Tinggi","Rendah") -> Tinggi | I28: =IF(AND(G28="Tinggi",H28="Tinggi"),"I - Maju & Tumbuh Cepat",IF(AND(G28="Tinggi",H28="Rendah"),"II - Maju tapi Tertekan",IF(AND(G28="Rendah",H28="Rendah"),"III - Relatif Tertinggal","IV - Berkembang Cepat"))) -> I - Maju & Tumbuh Cepat
A29: Kota Batam | B29: 2023 | C29: ='3. Total PDRB & Per Kapita'!F24 -> 101.17091 | D29: ='4. Laju Pertumbuhan'!D7 -> 0.071353613 | E29: ='3. Total PDRB & Per Kapita'!F32 -> 91.416579 | F29: ='4. Laju Pertumbuhan'!D9 -> 0.063154784 | G29: =IF(C29>=E29,"Tinggi","Rendah") -> Tinggi | H29: =IF(D29>=F29,"Tinggi","Rendah") -> Tinggi | I29: =IF(AND(G29="Tinggi",H29="Tinggi"),"I - Maju & Tumbuh Cepat",IF(AND(G29="Tinggi",H29="Rendah"),"II - Maju tapi Tertekan",IF(AND(G29="Rendah",H29="Rendah"),"III - Relatif Tertinggal","IV - Berkembang Cepat"))) -> I - Maju & Tumbuh Cepat
A30: Kota Batam | B30: 2024 | C30: ='3. Total PDRB & Per Kapita'!G24 -> 107.46009 | D30: ='4. Laju Pertumbuhan'!E7 -> 0.079339583 | E30: ='3. Total PDRB & Per Kapita'!G32 -> 96.438851 | F30: ='4. Laju Pertumbuhan'!E9 -> 0.069963844 | G30: =IF(C30>=E30,"Tinggi","Rendah") -> Tinggi | H30: =IF(D30>=F30,"Tinggi","Rendah") -> Tinggi | I30: =IF(AND(G30="Tinggi",H30="Tinggi"),"I - Maju & Tumbuh Cepat",IF(AND(G30="Tinggi",H30="Rendah"),"II - Maju tapi Tertekan",IF(AND(G30="Rendah",H30="Rendah"),"III - Relatif Tertinggal","IV - Berkembang Cepat"))) -> I - Maju & Tumbuh Cepat
A31: Kota Batam | B31: 2025 | C31: ='3. Total PDRB & Per Kapita'!H24 -> 112.46015 | D31: ='4. Laju Pertumbuhan'!F7 -> 0.06294536 | E31: ='3. Total PDRB & Per Kapita'!H32 -> 100.73452 | F31: ='4. Laju Pertumbuhan'!F9 -> 0.058977038 | G31: =IF(C31>=E31,"Tinggi","Rendah") -> Tinggi | H31: =IF(D31>=F31,"Tinggi","Rendah") -> Tinggi | I31: =IF(AND(G31="Tinggi",H31="Tinggi"),"I - Maju & Tumbuh Cepat",IF(AND(G31="Tinggi",H31="Rendah"),"II - Maju tapi Tertekan",IF(AND(G31="Rendah",H31="Rendah"),"III - Relatif Tertinggal","IV - Berkembang Cepat"))) -> I - Maju & Tumbuh Cepat
A32: Kota Tanjungpinang | B32: 2021 | C32: ='3. Total PDRB & Per Kapita'!D28 -> 61.079594 | D32: ='4. Laju Pertumbuhan'!B8 -> 0.0058823867 | E32: ='3. Total PDRB & Per Kapita'!D32 -> 83.827871 | F32: ='4. Laju Pertumbuhan'!B9 -> 0.032376745 | G32: =IF(C32>=E32,"Tinggi","Rendah") -> Rendah | H32: =IF(D32>=F32,"Tinggi","Rendah") -> Rendah | I32: =IF(AND(G32="Tinggi",H32="Tinggi"),"I - Maju & Tumbuh Cepat",IF(AND(G32="Tinggi",H32="Rendah"),"II - Maju tapi Tertekan",IF(AND(G32="Rendah",H32="Rendah"),"III - Relatif Tertinggal","IV - Berkembang Cepat"))) -> III - Relatif Tertinggal
A33: Kota Tanjungpinang | B33: 2022 | C33: ='3. Total PDRB & Per Kapita'!E28 -> 62.866408 | D33: ='4. Laju Pertumbuhan'!C8 -> 0.041181266 | E33: ='3. Total PDRB & Per Kapita'!E32 -> 87.24869 | F33: ='4. Laju Pertumbuhan'!C9 -> 0.056540109 | G33: =IF(C33>=E33,"Tinggi","Rendah") -> Rendah | H33: =IF(D33>=F33,"Tinggi","Rendah") -> Rendah | I33: =IF(AND(G33="Tinggi",H33="Tinggi"),"I - Maju & Tumbuh Cepat",IF(AND(G33="Tinggi",H33="Rendah"),"II - Maju tapi Tertekan",IF(AND(G33="Rendah",H33="Rendah"),"III - Relatif Tertinggal","IV - Berkembang Cepat"))) -> III - Relatif Tertinggal
A34: Kota Tanjungpinang | B34: 2023 | C34: ='3. Total PDRB & Per Kapita'!F28 -> 65.218872 | D34: ='4. Laju Pertumbuhan'!D8 -> 0.049215007 | E34: ='3. Total PDRB & Per Kapita'!F32 -> 91.416579 | F34: ='4. Laju Pertumbuhan'!D9 -> 0.063154784 | G34: =IF(C34>=E34,"Tinggi","Rendah") -> Rendah | H34: =IF(D34>=F34,"Tinggi","Rendah") -> Rendah | I34: =IF(AND(G34="Tinggi",H34="Tinggi"),"I - Maju & Tumbuh Cepat",IF(AND(G34="Tinggi",H34="Rendah"),"II - Maju tapi Tertekan",IF(AND(G34="Rendah",H34="Rendah"),"III - Relatif Tertinggal","IV - Berkembang Cepat"))) -> III - Relatif Tertinggal
A35: Kota Tanjungpinang | B35: 2024 | C35: ='3. Total PDRB & Per Kapita'!G28 -> 66.944952 | D35: ='4. Laju Pertumbuhan'!E8 -> 0.037786628 | E35: ='3. Total PDRB & Per Kapita'!G32 -> 96.438851 | F35: ='4. Laju Pertumbuhan'!E9 -> 0.069963844 | G35: =IF(C35>=E35,"Tinggi","Rendah") -> Rendah | H35: =IF(D35>=F35,"Tinggi","Rendah") -> Rendah | I35: =IF(AND(G35="Tinggi",H35="Tinggi"),"I - Maju & Tumbuh Cepat",IF(AND(G35="Tinggi",H35="Rendah"),"II - Maju tapi Tertekan",IF(AND(G35="Rendah",H35="Rendah"),"III - Relatif Tertinggal","IV - Berkembang Cepat"))) -> III - Relatif Tertinggal
A36: Kota Tanjungpinang | B36: 2025 | C36: ='3. Total PDRB & Per Kapita'!H28 -> 69.50771 | D36: ='4. Laju Pertumbuhan'!F8 -> 0.049345255 | E36: ='3. Total PDRB & Per Kapita'!H32 -> 100.73452 | F36: ='4. Laju Pertumbuhan'!F9 -> 0.058977038 | G36: =IF(C36>=E36,"Tinggi","Rendah") -> Rendah | H36: =IF(D36>=F36,"Tinggi","Rendah") -> Rendah | I36: =IF(AND(G36="Tinggi",H36="Tinggi"),"I - Maju & Tumbuh Cepat",IF(AND(G36="Tinggi",H36="Rendah"),"II - Maju tapi Tertekan",IF(AND(G36="Rendah",H36="Rendah"),"III - Relatif Tertinggal","IV - Berkembang Cepat"))) -> III - Relatif Tertinggal
A38: Logika Kuadran:
A39: Kuadran I (hijau) - Maju & Tumbuh Cepat : PDRB per kapita >= provinsi, DAN pertumbuhan >= provinsi
A40: Kuadran II (kuning) - Maju tapi Tertekan : PDRB per kapita >= provinsi, TAPI pertumbuhan < provinsi
A41: Kuadran III(merah) - Relatif Tertinggal : PDRB per kapita < provinsi, DAN pertumbuhan < provinsi
...
